# try...catch...finally
## 정의
* javascript에서 예외 처리(Exception handling)를 구현하는 방법이다.
* 에러 처리 코드를 미리 등록해두고 에러 발생 시 에러 처리 코드를 실행하는 방식으로 작동한다.
* 돌발적인 에러 발생 시 스크립트가 중단되는 것을 방지하고 해당 에러에 따른 대응 코드를 작동시킨다. try...catch를 통해 오류를 잡아낼 경우 스크립트가 중단되지 않고 다음 과정으로 넘어간다.
* 발생한 에러를 처리하지 않으면 프로그램은 강제 종료될 수 있다.
* `try..catch..finally` 문을 이용해 발생한 에러를 처리하면 프로그램의 강제 종료를 방지할 수 있다.
* `try...catch` 수행문은 `try`블록과 `catch`블록이나 `finally`블록, 혹은 둘 다로 이뤄져 있다.

## 구문
```js
try {
  try 수행문
} catch [(예외변수)] {
  catch 수행문
} [finally {
  finally 수행문
}]
```
* `finally` 문은 불필요하다면 생략 가능하다.
* `catch` 문도 생략 가능하지만 생략한다면 오류 처리를 할 수 없다. 그럴 경우, `try` 문을 사용하는 의미가 없어지므로 생략하지 않는다.

### try문
* `try` 블록의 코드가 먼저 실행된다.
* 에러 발생 가능성이 있는 코드가 있다.

### catch문
* `try` 문에서 에러가 발생된다면, `catch` 블록이 실행된다.
* `매개변수(parameter)` 로 에러 객체를 받을 수 있다.
* `매개변수(parameter)` 로 받은 에러 객체는 `instanceof` 연산자를 이용해 분기하여 처리할 수 있다.

### finally문
* 에러 발생 유무와 상관없이 항상 실행된다.
* 생략 가능하다.

<br>

## Catch binding
- `try`블록에서 예외가 발생하면 예외문(예: `catch(e)`의 경우 e)이 예외값을 보유한다. 이 바인딩을 사용하여 발생한 예외에 대한 정보를 가져올 수 있다. 이 바인딩은 `catch`블록 범위에서만 사용할 수 있다.
- 단일 식별자일 필요는 없으며, 구조 분해 할당을 사용하여 한번에 여러 식별자를 할당할 수 있다.

```js
try {
  throw new TypeError("oops"); // TypeError 객체 생성
} catch ({ name, message }) {
  console.log(name); // "TypeError"
  console.log(message); // "oops"
}
```
- `catch`절에서 생성된 바인딩은 같은 `catch`스코프에 존재하므로, `catch`블록에 선언된 변수는 바인딩과 같은 이름을 가질 수 없다.(예: `name`, `message`)

## 조건부 `catch`블록
- `try...catch` 블록을 `if...else` `if...else` 구조와 결합하여 "조건부 `catch` 블록"을 만들 수 있다.
  ```js
  try {
    myroutine(); // 세 가지 유형의 예외가 발생할 수 있음
  } catch (e) {
    if (e instanceof TypeError) {
      // TypeError 예외를 처리하는 문장들
    } else if (e instanceof RangeError) {
      // RangeError 예외를 처리하는 문장들
    } else if (e instanceof EvalError) {
      // EvalError 예외를 처리하는 문장들
    } else {
      // 지정되지 않은 다른 예외를 처리하는 문장들
      logMyErrors(e); // 예외 객체를 Error handler에 전달
    }
  }
  ```
- 이것은 특정한 예상되는 에러들만 조용히 처리하고, 다른 경우에는 에러를 다시 던지는 일반적인 사용 사례다.
### 에러의 종류
MDN: [JavaScript error reference](https://developer.mozilla.org/en-US/docs/Web/JavaScript/Reference/Errors)

* Error: 일반적인 에러 객체
* InternalError: JavaScript 엔진 내부에서 발생한 오류를 나타내는 에러 객체
* RangeError: 숫자값의 허용 범위를 벗어났을 때 발생하는 에러 객체
* ReferenceError: 참조할 수 없는 식별자를 참조했을 때 발생하는 에러 객체
* SyntaxError: 문법에 맞지 않을 때 발생하는 에러 객체
* TypeError: 피연산자 또는 인수의 데이터 타입이 유효하지 않을 때 발생하는 에러 객체
* URIError: encodeURI 또는 decodeURI 함수에 부적절한 인수를 전달했을 때 발생하는 에러 객체

## 중첩된 `try` 블록

```js
try {
  try {
    throw new Error("oops");
  } finally {
    console.log("finally");
  }
} catch (ex) {
  console.error("outer", ex.message);
}

// 출력:
// "finally"
// "outer" "oops"
```
* 내부 `try` 블록에 `catch` 블록을 추가하여 예외를 처리.

<br>

```js
try {
  try {
    throw new Error("oops");
  } catch (ex) {
    console.error("inner", ex.message);
  } finally {
    console.log("finally");
  }
} catch (ex) {
  console.error("outer", ex.message);
}

// 출력:
// "inner" "oops"
// "finally"
```
* 내부 `catch` 블록에 Error를 재발생.

<br>

```js
try {
  try {
    throw new Error("oops");
  } catch (ex) {
    console.error("inner", ex.message);
    throw ex;
  } finally {
    console.log("finally");
  }
} catch (ex) {
  console.error("outer", ex.message);
}

// 출력:
// "inner" "oops"
// "finally"
// "outer" "oops"
```
- 예외를 다시 던지지 않는 한, 가장 가까운  `catch` 블록에서 예외가 한 번만 처리된다. 물론 `catch` 블록 내부에서 새로운 예외가 발생할 경우(예: `catch` 블록에서 예외를 발생시키는 코드 실행), 이는 외부 블록에서 잡힌다.

## `finally` 블록에서의 반환
- 만약 `finally` 블록에서 반환값이 있는 경우, 이 값은 `try-catch-finally` 문 전체의 반환값이 된다. 이는 `try` 블록이나 `catch` 블록에서의 반환문에 관계없이 적용된다. 이는 `catch` 블록 내에서 발생한 예외에도 적용된다.

  ```js
  (() => {
    try {
      try {
        throw new Error("oops");
      } catch (ex) {
        console.error("inner", ex.message);
        throw ex;
      } finally {
        console.log("finally");
        return;
      }
    } catch (ex) {
      console.error("outer", ex.message);
    }
  })();

  // 출력:
  // "inner" "oops"
  // "finally"
  ```
- `finally` 블록에서의 반환 때문에 바깥 "oops"는 발생하지 않는다. `catch` 블록에서 반환된 값도 동일하게 적용된다.

<br>

# throw
## 정의
* Error 생성자 함수로 생성한 에러 객체를 발생시키기 위해 `throw` 문을 사용한다.


## 구문
```js
throw 표현식;
```

## 예문
```js
try {
  console.log(saveImg({name: "img.png", size: 10}));
} catch (e) {
  console.error(e.message);
}

function saveImg(img) {
  return resizeImg(img);
}

function resizeImg(img) {
  if (img.size < 25) {
    throw new Error("too small!");
  }

  return {...img, size: 25};
}
```
* throw 된 에러를 처리하지 않으면 해당 에러가 발생한 함수를 호출한 위치로 에러가 전파된다.
* throw 된 에러를 어디서도 처리하지 않으면 프로그램은 강제 종료된다.

<br>

```js
let openDrawer = false; // 서랍은 계산 중이 아닐 경우는 항상 닫혀있어야 한다.

const getChange = (price, money) => {
  try {
    openDrawer = true;
    if (price > money) {
      throw new Error(`${price - money}원 더 주세요.`);
    }
    return `여기 잔돈 ${money - price}원 입니다.`;
  } catch(e) {
    return e.message;
  } finally {
    openDrawer = false;
  }
}

console.log(getChange(9900, 9000)); // "900원 더 주세요."
console.log(getChange(7500, 10000)); // "여기 잔돈 2500원 입니다."
```
* `try` 문과 `catch` 문에서 값을 반환하면, `finally` 블록을 실행이 끝난 뒤 반환된다.
